
Training model:
/raid/home/automathon_2024/account8/.local/lib/python3.10/site-packages/torch/nn/modules/conv.py:605: UserWarning: Plan failed with a cudnnException: CUDNN_BACKEND_EXECUTION_PLAN_DESCRIPTOR: cudnnFinalize Descriptor Failed cudnn_status: CUDNN_STATUS_NOT_SUPPORTED (Triggered internally at ../aten/src/ATen/native/cudnn/Conv_v8.cpp:919.)
  return F.conv3d(
Traceback (most recent call last):
  File "/raid/home/automathon_2024/account8/.local/lib/python3.10/site-packages/torchinfo/torchinfo.py", line 295, in forward_pass
    _ = model(*x, **kwargs)
  File "/raid/home/automathon_2024/account8/.local/lib/python3.10/site-packages/torch/nn/modules/module.py", line 1532, in _wrapped_call_impl
    return self._call_impl(*args, **kwargs)
  File "/raid/home/automathon_2024/account8/.local/lib/python3.10/site-packages/torch/nn/modules/module.py", line 1582, in _call_impl
    result = forward_call(*args, **kwargs)
  File "/raid/home/automathon_2024/account8/automathon-2024/run.py", line 247, in forward
    x = self.relu(self.bn2(self.conv2(x)))
  File "/raid/home/automathon_2024/account8/.local/lib/python3.10/site-packages/torch/nn/modules/module.py", line 1532, in _wrapped_call_impl
    return self._call_impl(*args, **kwargs)
  File "/raid/home/automathon_2024/account8/.local/lib/python3.10/site-packages/torch/nn/modules/module.py", line 1582, in _call_impl
    result = forward_call(*args, **kwargs)
  File "/raid/home/automathon_2024/account8/.local/lib/python3.10/site-packages/torch/nn/modules/conv.py", line 610, in forward
    return self._conv_forward(input, self.weight, self.bias)
  File "/raid/home/automathon_2024/account8/.local/lib/python3.10/site-packages/torch/nn/modules/conv.py", line 605, in _conv_forward
    return F.conv3d(
RuntimeError: Given groups=1, weight of size [32, 16, 3, 3, 3], expected input[32, 15, 10, 128, 128] to have 16 channels, but got 15 channels instead
The above exception was the direct cause of the following exception:
Traceback (most recent call last):
  File "/raid/home/automathon_2024/account8/automathon-2024/run.py", line 301, in <module>
    summary(model, input_size=(batch_size, 3, 10, 256, 256))
  File "/raid/home/automathon_2024/account8/.local/lib/python3.10/site-packages/torchinfo/torchinfo.py", line 223, in summary
    summary_list = forward_pass(
  File "/raid/home/automathon_2024/account8/.local/lib/python3.10/site-packages/torchinfo/torchinfo.py", line 304, in forward_pass
    raise RuntimeError(
RuntimeError: Failed to run torchinfo. See above stack traces for more details. Executed layers up to: [Conv3d: 1, BatchNorm3d: 1, ReLU: 1, MaxPool3d: 1]