
Training model:
/raid/home/automathon_2024/account8/.local/lib/python3.10/site-packages/torch/nn/modules/conv.py:605: UserWarning: Plan failed with an OutOfMemoryError: CUDA out of memory. Tried to allocate 5.24 GiB. GPU  (Triggered internally at ../aten/src/ATen/native/cudnn/Conv_v8.cpp:924.)
  return F.conv3d(
/raid/home/automathon_2024/account8/.local/lib/python3.10/site-packages/torch/nn/modules/conv.py:605: UserWarning: Plan failed with an OutOfMemoryError: CUDA out of memory. Tried to allocate 5.31 GiB. GPU  (Triggered internally at ../aten/src/ATen/native/cudnn/Conv_v8.cpp:924.)
  return F.conv3d(
Traceback (most recent call last):
  File "/raid/home/automathon_2024/account8/.local/lib/python3.10/site-packages/torchinfo/torchinfo.py", line 295, in forward_pass
    _ = model(*x, **kwargs)
  File "/raid/home/automathon_2024/account8/.local/lib/python3.10/site-packages/torch/nn/modules/module.py", line 1532, in _wrapped_call_impl
    return self._call_impl(*args, **kwargs)
  File "/raid/home/automathon_2024/account8/.local/lib/python3.10/site-packages/torch/nn/modules/module.py", line 1582, in _call_impl
    result = forward_call(*args, **kwargs)
  File "/raid/home/automathon_2024/account8/automathon-2024/run.py", line 244, in forward
    x = self.relu(self.bn1(self.conv1(x)))
  File "/raid/home/automathon_2024/account8/.local/lib/python3.10/site-packages/torch/nn/modules/module.py", line 1532, in _wrapped_call_impl
    return self._call_impl(*args, **kwargs)
  File "/raid/home/automathon_2024/account8/.local/lib/python3.10/site-packages/torch/nn/modules/module.py", line 1582, in _call_impl
    result = forward_call(*args, **kwargs)
  File "/raid/home/automathon_2024/account8/.local/lib/python3.10/site-packages/torch/nn/modules/batchnorm.py", line 175, in forward
    return F.batch_norm(
  File "/raid/home/automathon_2024/account8/.local/lib/python3.10/site-packages/torch/nn/functional.py", line 2509, in batch_norm
    return torch.batch_norm(
torch.cuda.OutOfMemoryError: CUDA out of memory. Tried to allocate 5.00 GiB. GPU
The above exception was the direct cause of the following exception:
Traceback (most recent call last):
  File "/raid/home/automathon_2024/account8/automathon-2024/run.py", line 304, in <module>
    summary(model, input_size=(batch_size, 3, 10, 256, 256))
  File "/raid/home/automathon_2024/account8/.local/lib/python3.10/site-packages/torchinfo/torchinfo.py", line 223, in summary
    summary_list = forward_pass(
  File "/raid/home/automathon_2024/account8/.local/lib/python3.10/site-packages/torchinfo/torchinfo.py", line 304, in forward_pass
    raise RuntimeError(
RuntimeError: Failed to run torchinfo. See above stack traces for more details. Executed layers up to: [Conv3d: 1]